2019-03-11 23:39:44,750 INFO: Microblog startup [in /Users/taylor/Documents/Developer/flask-microblog/flask-web/app/__init__.py:46]
2019-03-12 22:33:47,499 INFO: Microblog startup [in /Users/taylor/Documents/Developer/flask-microblog/flask-web/app/__init__.py:46]
2019-03-12 23:37:44,489 INFO: Microblog startup [in /Users/taylor/Documents/Developer/flask-microblog/flask-web/app/__init__.py:46]
2019-03-12 23:38:00,210 INFO: Microblog startup [in /Users/taylor/Documents/Developer/flask-microblog/flask-web/app/__init__.py:46]
2019-03-12 23:41:26,614 INFO: Microblog startup [in /Users/taylor/Documents/Developer/flask-microblog/flask-web/app/__init__.py:46]
2019-03-12 23:43:19,892 INFO: Microblog startup [in /Users/taylor/Documents/Developer/flask-microblog/flask-web/app/__init__.py:46]
2019-03-13 00:01:50,736 INFO: Microblog startup [in /Users/taylor/Documents/Developer/flask-microblog/flask-web/app/__init__.py:46]
2019-03-13 00:02:03,689 ERROR: Exception on /explore [GET] [in /Users/taylor/.virtualenvs/microblog/lib/python3.6/site-packages/flask/app.py:1761]
Traceback (most recent call last):
  File "/Users/taylor/.virtualenvs/microblog/lib/python3.6/site-packages/flask/app.py", line 2292, in wsgi_app
    response = self.full_dispatch_request()
  File "/Users/taylor/.virtualenvs/microblog/lib/python3.6/site-packages/flask/app.py", line 1815, in full_dispatch_request
    rv = self.handle_user_exception(e)
  File "/Users/taylor/.virtualenvs/microblog/lib/python3.6/site-packages/flask/app.py", line 1718, in handle_user_exception
    reraise(exc_type, exc_value, tb)
  File "/Users/taylor/.virtualenvs/microblog/lib/python3.6/site-packages/flask/_compat.py", line 35, in reraise
    raise value
  File "/Users/taylor/.virtualenvs/microblog/lib/python3.6/site-packages/flask/app.py", line 1813, in full_dispatch_request
    rv = self.dispatch_request()
  File "/Users/taylor/.virtualenvs/microblog/lib/python3.6/site-packages/flask/app.py", line 1799, in dispatch_request
    return self.view_functions[rule.endpoint](**req.view_args)
  File "/Users/taylor/.virtualenvs/microblog/lib/python3.6/site-packages/flask_login/utils.py", line 261, in decorated_view
    return func(*args, **kwargs)
  File "/Users/taylor/Documents/Developer/flask-microblog/flask-web/app/routes.py", line 35, in explore
    page, app.config['POST_PER_PAGE'], False
KeyError: 'POST_PER_PAGE'
2019-03-13 00:02:08,841 ERROR: Exception on /index [GET] [in /Users/taylor/.virtualenvs/microblog/lib/python3.6/site-packages/flask/app.py:1761]
Traceback (most recent call last):
  File "/Users/taylor/.virtualenvs/microblog/lib/python3.6/site-packages/flask/app.py", line 2292, in wsgi_app
    response = self.full_dispatch_request()
  File "/Users/taylor/.virtualenvs/microblog/lib/python3.6/site-packages/flask/app.py", line 1815, in full_dispatch_request
    rv = self.handle_user_exception(e)
  File "/Users/taylor/.virtualenvs/microblog/lib/python3.6/site-packages/flask/app.py", line 1718, in handle_user_exception
    reraise(exc_type, exc_value, tb)
  File "/Users/taylor/.virtualenvs/microblog/lib/python3.6/site-packages/flask/_compat.py", line 35, in reraise
    raise value
  File "/Users/taylor/.virtualenvs/microblog/lib/python3.6/site-packages/flask/app.py", line 1813, in full_dispatch_request
    rv = self.dispatch_request()
  File "/Users/taylor/.virtualenvs/microblog/lib/python3.6/site-packages/flask/app.py", line 1799, in dispatch_request
    return self.view_functions[rule.endpoint](**req.view_args)
  File "/Users/taylor/.virtualenvs/microblog/lib/python3.6/site-packages/flask_login/utils.py", line 261, in decorated_view
    return func(*args, **kwargs)
  File "/Users/taylor/Documents/Developer/flask-microblog/flask-web/app/routes.py", line 25, in index
    page, app.config['POST_PER_PAGE'], False
KeyError: 'POST_PER_PAGE'
2019-03-13 00:02:13,381 ERROR: Exception on /index [GET] [in /Users/taylor/.virtualenvs/microblog/lib/python3.6/site-packages/flask/app.py:1761]
Traceback (most recent call last):
  File "/Users/taylor/.virtualenvs/microblog/lib/python3.6/site-packages/flask/app.py", line 2292, in wsgi_app
    response = self.full_dispatch_request()
  File "/Users/taylor/.virtualenvs/microblog/lib/python3.6/site-packages/flask/app.py", line 1815, in full_dispatch_request
    rv = self.handle_user_exception(e)
  File "/Users/taylor/.virtualenvs/microblog/lib/python3.6/site-packages/flask/app.py", line 1718, in handle_user_exception
    reraise(exc_type, exc_value, tb)
  File "/Users/taylor/.virtualenvs/microblog/lib/python3.6/site-packages/flask/_compat.py", line 35, in reraise
    raise value
  File "/Users/taylor/.virtualenvs/microblog/lib/python3.6/site-packages/flask/app.py", line 1813, in full_dispatch_request
    rv = self.dispatch_request()
  File "/Users/taylor/.virtualenvs/microblog/lib/python3.6/site-packages/flask/app.py", line 1799, in dispatch_request
    return self.view_functions[rule.endpoint](**req.view_args)
  File "/Users/taylor/.virtualenvs/microblog/lib/python3.6/site-packages/flask_login/utils.py", line 261, in decorated_view
    return func(*args, **kwargs)
  File "/Users/taylor/Documents/Developer/flask-microblog/flask-web/app/routes.py", line 25, in index
    page, app.config['POST_PER_PAGE'], False
KeyError: 'POST_PER_PAGE'
2019-03-13 00:02:13,779 ERROR: Exception on /index [GET] [in /Users/taylor/.virtualenvs/microblog/lib/python3.6/site-packages/flask/app.py:1761]
Traceback (most recent call last):
  File "/Users/taylor/.virtualenvs/microblog/lib/python3.6/site-packages/flask/app.py", line 2292, in wsgi_app
    response = self.full_dispatch_request()
  File "/Users/taylor/.virtualenvs/microblog/lib/python3.6/site-packages/flask/app.py", line 1815, in full_dispatch_request
    rv = self.handle_user_exception(e)
  File "/Users/taylor/.virtualenvs/microblog/lib/python3.6/site-packages/flask/app.py", line 1718, in handle_user_exception
    reraise(exc_type, exc_value, tb)
  File "/Users/taylor/.virtualenvs/microblog/lib/python3.6/site-packages/flask/_compat.py", line 35, in reraise
    raise value
  File "/Users/taylor/.virtualenvs/microblog/lib/python3.6/site-packages/flask/app.py", line 1813, in full_dispatch_request
    rv = self.dispatch_request()
  File "/Users/taylor/.virtualenvs/microblog/lib/python3.6/site-packages/flask/app.py", line 1799, in dispatch_request
    return self.view_functions[rule.endpoint](**req.view_args)
  File "/Users/taylor/.virtualenvs/microblog/lib/python3.6/site-packages/flask_login/utils.py", line 261, in decorated_view
    return func(*args, **kwargs)
  File "/Users/taylor/Documents/Developer/flask-microblog/flask-web/app/routes.py", line 25, in index
    page, app.config['POST_PER_PAGE'], False
KeyError: 'POST_PER_PAGE'
2019-03-13 00:02:13,957 ERROR: Exception on /index [GET] [in /Users/taylor/.virtualenvs/microblog/lib/python3.6/site-packages/flask/app.py:1761]
Traceback (most recent call last):
  File "/Users/taylor/.virtualenvs/microblog/lib/python3.6/site-packages/flask/app.py", line 2292, in wsgi_app
    response = self.full_dispatch_request()
  File "/Users/taylor/.virtualenvs/microblog/lib/python3.6/site-packages/flask/app.py", line 1815, in full_dispatch_request
    rv = self.handle_user_exception(e)
  File "/Users/taylor/.virtualenvs/microblog/lib/python3.6/site-packages/flask/app.py", line 1718, in handle_user_exception
    reraise(exc_type, exc_value, tb)
  File "/Users/taylor/.virtualenvs/microblog/lib/python3.6/site-packages/flask/_compat.py", line 35, in reraise
    raise value
  File "/Users/taylor/.virtualenvs/microblog/lib/python3.6/site-packages/flask/app.py", line 1813, in full_dispatch_request
    rv = self.dispatch_request()
  File "/Users/taylor/.virtualenvs/microblog/lib/python3.6/site-packages/flask/app.py", line 1799, in dispatch_request
    return self.view_functions[rule.endpoint](**req.view_args)
  File "/Users/taylor/.virtualenvs/microblog/lib/python3.6/site-packages/flask_login/utils.py", line 261, in decorated_view
    return func(*args, **kwargs)
  File "/Users/taylor/Documents/Developer/flask-microblog/flask-web/app/routes.py", line 25, in index
    page, app.config['POST_PER_PAGE'], False
KeyError: 'POST_PER_PAGE'
2019-03-13 00:02:14,124 ERROR: Exception on /index [GET] [in /Users/taylor/.virtualenvs/microblog/lib/python3.6/site-packages/flask/app.py:1761]
Traceback (most recent call last):
  File "/Users/taylor/.virtualenvs/microblog/lib/python3.6/site-packages/flask/app.py", line 2292, in wsgi_app
    response = self.full_dispatch_request()
  File "/Users/taylor/.virtualenvs/microblog/lib/python3.6/site-packages/flask/app.py", line 1815, in full_dispatch_request
    rv = self.handle_user_exception(e)
  File "/Users/taylor/.virtualenvs/microblog/lib/python3.6/site-packages/flask/app.py", line 1718, in handle_user_exception
    reraise(exc_type, exc_value, tb)
  File "/Users/taylor/.virtualenvs/microblog/lib/python3.6/site-packages/flask/_compat.py", line 35, in reraise
    raise value
  File "/Users/taylor/.virtualenvs/microblog/lib/python3.6/site-packages/flask/app.py", line 1813, in full_dispatch_request
    rv = self.dispatch_request()
  File "/Users/taylor/.virtualenvs/microblog/lib/python3.6/site-packages/flask/app.py", line 1799, in dispatch_request
    return self.view_functions[rule.endpoint](**req.view_args)
  File "/Users/taylor/.virtualenvs/microblog/lib/python3.6/site-packages/flask_login/utils.py", line 261, in decorated_view
    return func(*args, **kwargs)
  File "/Users/taylor/Documents/Developer/flask-microblog/flask-web/app/routes.py", line 25, in index
    page, app.config['POST_PER_PAGE'], False
KeyError: 'POST_PER_PAGE'
